<?xml version="1.0" ?>
<!-- =================================================================================== -->
<!-- |    This document was autogenerated by xacro from mario.urdf.xacro               | -->
<!-- |    EDITING THIS FILE BY HAND IS NOT RECOMMENDED                                 | -->
<!-- =================================================================================== -->
<!-- URDF for MARIO-->
<robot name="mario">
  <!--            -->
  <!-- Properties -->
  <!--            -->
  <!-- Dummy link that the robot is fixed to -->
  <link name="base_link"/>
  <!-- Mount Link -->
  <link name="mount_link">
    <visual>
      <origin rpy="0 0 0" xyz="0 0 0"/>
      <geometry>
        <mesh filename="file:///home/astralab/ros/mario_ws/install/mario_description/share/mario_description/meshes/visual/floating_base.dae"/>
      </geometry>
    </visual>
    <collision>
      <origin rpy="0 0 0" xyz="0 0 0"/>
      <geometry>
        <mesh filename="file:///home/astralab/ros/mario_ws/install/mario_description/share/mario_description/meshes/collision/floating_base_collision.stl"/>
      </geometry>
    </collision>
    <inertial>
      <origin rpy="0 0 0" xyz="-0.002 0.003 0.178"/>
      <mass value="30.631"/>
      <inertia ixx="2.192" ixy="1e-6" ixz="1e-6" iyy="2.14" iyz="1e-6" izz="1.778"/>
    </inertial>
  </link>
  <!-- Mount Joint -->
  <joint name="mount_joint" type="fixed">
    <parent link="base_link"/>
    <child link="mount_link"/>
    <origin rpy="0 0 0" xyz="0 0 0"/>
  </joint>
  <gazebo reference="mount_link">
    <mu1 value="0.2"/>
    <mu2 value="0.2"/>
  </gazebo>
  <!-- Body Link -->
  <link name="body_link">
    <visual>
      <origin rpy="0 0 0" xyz="0 0 0"/>
      <geometry>
        <mesh filename="file:///home/astralab/ros/mario_ws/install/mario_description/share/mario_description/meshes/visual/torso_mounted_tools.dae"/>
      </geometry>
    </visual>
    <collision>
      <origin rpy="0 0 0" xyz="0 0 0"/>
      <geometry>
        <mesh filename="file:///home/astralab/ros/mario_ws/install/mario_description/share/mario_description/meshes/collision/torso_mounted_tools_collision.stl"/>
      </geometry>
    </collision>
    <inertial>
      <origin rpy="0 0 0" xyz="-0.173 0.00 0.004"/>
      <mass value="46.273"/>
      <inertia ixx="1.263" ixy="1e-6" ixz="1e-6" iyy="2.184" iyz="1e-6" izz="2.174"/>
    </inertial>
  </link>
  <!-- Body Joint -->
  <joint name="body_joint" type="fixed">
    <parent link="mount_link"/>
    <child link="body_link"/>
    <origin rpy="0 0 0" xyz="0 0 0.9746"/>
  </joint>
  <gazebo reference="body_link">
    <mu1 value="0.001"/>
    <mu2 value="0.001"/>
  </gazebo>
  <joint name="arm1_base_joint" type="fixed">
    <parent link="body_link"/>
    <child link="arm1_base_link"/>
    <origin rpy="0 0.785398 0" xyz="0.03157042 0.0 0.2555044"/>
  </joint>
  <link name="arm1_base_link">
    <visual>
      <origin rpy="0 0 0" xyz="0 0 0"/>
      <geometry>
        <mesh filename="file:///home/astralab/ros/mario_ws/install/mario_description/share/mario_description/meshes/visual/base_link.dae"/>
      </geometry>
    </visual>
    <collision>
      <origin rpy="0 0 0" xyz="0 0 0"/>
      <geometry>
        <mesh filename="file:///home/astralab/ros/mario_ws/install/mario_description/share/mario_description/meshes/collision/base_link_collision.stl"/>
      </geometry>
    </collision>
    <!-- <xacro:if value="${mesh == mount_mesh}">
      <inertial>
        <origin
          xyz="0 0 0.233815804"
          rpy="${mesh_offset_rpy}" />
        <mass value="21.359904"/>
        <inertia ixx="2.013" ixy="5.778e-15" ixz="4.402e-11" iyy="2.016" iyz="1.573E-03" izz="0.4845"/>
      </inertial>
    </xacro:if>

    <xacro:if value="${mesh == body_mesh}">
      <inertial>
        <origin
          xyz="0.000285284 0.00001441 -0.016716995"
          rpy="${mesh_offset_rpy}" />
        <mass value="31.791789"/>
        <inertia ixx="1.910" ixy="-0.0002148" ixz="0.001069" iyy="1.379" iyz="0.000011660298" izz="1.069"/>
      </inertial>
    </xacro:if>     -->
    <inertial>
      <origin rpy="0 0 0" xyz="-0.000300666 -2.93177e-06 0.0856931"/>
      <mass value="2.9406587184754085"/>
      <inertia ixx="0.01240919194880053" ixy="-6.681227801256974e-07" ixz="-4.2742940760836404e-05" iyy="0.012467411766498215" iyz="-7.075356089603068e-07" izz="0.006257407233473556"/>
    </inertial>
  </link>
  <gazebo reference="arm1_base_link">
    <mu1 value="0.2"/>
    <mu2 value="0.2"/>
  </gazebo>
  <joint name="arm1_joint1" type="revolute">
    <parent link="arm1_base_link"/>
    <child link="arm1_link1"/>
    <origin rpy="0 0 0" xyz="0 0 0.364"/>
    <axis xyz="0 0 1"/>
    <limit effort="200" lower="-6.28" upper="6.28" velocity="0.314"/>
    <dynamics damping="16.6" friction="9.6"/>
  </joint>
  <transmission name="arm1_joint1_transmission">
    <type>transmission_interface/SimpleTransmission</type>
    <joint name="arm1_joint1">
      <hardwareInterface>hardware_interface/PositionJointInterface</hardwareInterface>
    </joint>
    <actuator name="arm1_joint1_actuator">
      <hardwareInterface>hardware_interface/PositionJointInterface</hardwareInterface>
      <mechanicalReduction>100</mechanicalReduction>
    </actuator>
  </transmission>
  <gazebo reference="arm1_joint1">
    <springStiffness value="0.0"/>
    <springReference value="0.0"/>
  </gazebo>
  <link name="arm1_link1">
    <visual>
      <origin rpy="0 0 0" xyz="0 0 0"/>
      <geometry>
        <mesh filename="file:///home/astralab/ros/mario_ws/install/mario_description/share/mario_description/meshes/visual/link1.dae"/>
      </geometry>
    </visual>
    <collision>
      <origin rpy="0 0 0" xyz="0 0 0"/>
      <geometry>
        <mesh filename="file:///home/astralab/ros/mario_ws/install/mario_description/share/mario_description/meshes/collision/link1_collision.stl"/>
      </geometry>
    </collision>
    <!-- <xacro:if value="${mesh == mount_mesh}">
      <inertial>
        <origin
          xyz="0 0 0.233815804"
          rpy="${mesh_offset_rpy}" />
        <mass value="21.359904"/>
        <inertia ixx="2.013" ixy="5.778e-15" ixz="4.402e-11" iyy="2.016" iyz="1.573E-03" izz="0.4845"/>
      </inertial>
    </xacro:if>

    <xacro:if value="${mesh == body_mesh}">
      <inertial>
        <origin
          xyz="0.000285284 0.00001441 -0.016716995"
          rpy="${mesh_offset_rpy}" />
        <mass value="31.791789"/>
        <inertia ixx="1.910" ixy="-0.0002148" ixz="0.001069" iyy="1.379" iyz="0.000011660298" izz="1.069"/>
      </inertial>
    </xacro:if>     -->
    <inertial>
      <origin rpy="0 0 0" xyz="-8.43196e-06 0.0341221 -0.0559626"/>
      <mass value="3.3482163929478057"/>
      <inertia ixx="0.020854379548931976" ixy="6.567223430941928e-07" ixz="-4.3588684092984624e-07" iyy="0.01871416353357244" iyz="-0.004171196153314615" izz="0.008087898002895265"/>
    </inertial>
  </link>
  <gazebo reference="arm1_link1">
    <mu1 value="0.2"/>
    <mu2 value="0.2"/>
  </gazebo>
  <joint name="arm1_joint2" type="revolute">
    <parent link="arm1_link1"/>
    <child link="arm1_link2"/>
    <origin rpy="1.5708 -1.5708 0" xyz="0 0 0"/>
    <axis xyz="0 0 1"/>
    <limit effort="200" lower="-2.3038346" upper="2.3038346" velocity="0.314"/>
    <dynamics damping="12.5" friction="12.1"/>
  </joint>
  <transmission name="arm1_joint2_transmission">
    <type>transmission_interface/SimpleTransmission</type>
    <joint name="arm1_joint2">
      <hardwareInterface>hardware_interface/PositionJointInterface</hardwareInterface>
    </joint>
    <actuator name="arm1_joint2_actuator">
      <hardwareInterface>hardware_interface/PositionJointInterface</hardwareInterface>
      <mechanicalReduction>100</mechanicalReduction>
    </actuator>
  </transmission>
  <gazebo reference="arm1_joint2">
    <springStiffness value="0.0"/>
    <springReference value="0.0"/>
  </gazebo>
  <link name="arm1_link2">
    <visual>
      <origin rpy="0 -3.1416 1.5708" xyz="0 0 0"/>
      <geometry>
        <mesh filename="file:///home/astralab/ros/mario_ws/install/mario_description/share/mario_description/meshes/visual/link2.dae"/>
      </geometry>
    </visual>
    <collision>
      <origin rpy="0 -3.1416 1.5708" xyz="0 0 0"/>
      <geometry>
        <mesh filename="file:///home/astralab/ros/mario_ws/install/mario_description/share/mario_description/meshes/collision/link2_collision.stl"/>
      </geometry>
    </collision>
    <!-- <xacro:if value="${mesh == mount_mesh}">
      <inertial>
        <origin
          xyz="0 0 0.233815804"
          rpy="${mesh_offset_rpy}" />
        <mass value="21.359904"/>
        <inertia ixx="2.013" ixy="5.778e-15" ixz="4.402e-11" iyy="2.016" iyz="1.573E-03" izz="0.4845"/>
      </inertial>
    </xacro:if>

    <xacro:if value="${mesh == body_mesh}">
      <inertial>
        <origin
          xyz="0.000285284 0.00001441 -0.016716995"
          rpy="${mesh_offset_rpy}" />
        <mass value="31.791789"/>
        <inertia ixx="1.910" ixy="-0.0002148" ixz="0.001069" iyy="1.379" iyz="0.000011660298" izz="1.069"/>
      </inertial>
    </xacro:if>     -->
    <inertial>
      <origin rpy="0 -3.1416 1.5708" xyz="7.13145e-05 -0.203029 -0.0324578"/>
      <mass value="5.070470527195393"/>
      <inertia ixx="0.11865370417075823" ixy="-2.375656313165855e-05" ixz="4.136754045829818e-06" iyy="0.009622141254146021" iyz="0.005416309225005912" izz="0.11597628036190748"/>
    </inertial>
  </link>
  <gazebo reference="arm1_link2">
    <mu1 value="0.2"/>
    <mu2 value="0.2"/>
  </gazebo>
  <joint name="arm1_joint3" type="revolute">
    <parent link="arm1_link2"/>
    <child link="arm1_link3"/>
    <origin rpy="-3.1416 0 -1.5708" xyz="0.39 0 0"/>
    <axis xyz="0 0 1"/>
    <limit effort="90" lower="-4.2236968" upper="0.061087" velocity="0.314"/>
    <dynamics damping="4.0" friction="5.5"/>
  </joint>
  <transmission name="arm1_joint3_transmission">
    <type>transmission_interface/SimpleTransmission</type>
    <joint name="arm1_joint3">
      <hardwareInterface>hardware_interface/PositionJointInterface</hardwareInterface>
    </joint>
    <actuator name="arm1_joint3_actuator">
      <hardwareInterface>hardware_interface/PositionJointInterface</hardwareInterface>
      <mechanicalReduction>100</mechanicalReduction>
    </actuator>
  </transmission>
  <gazebo reference="arm1_joint3">
    <springStiffness value="0.0"/>
    <springReference value="0.0"/>
  </gazebo>
  <link name="arm1_link3">
    <visual>
      <origin rpy="0 0 0" xyz="0 0 0"/>
      <geometry>
        <mesh filename="file:///home/astralab/ros/mario_ws/install/mario_description/share/mario_description/meshes/visual/link3.dae"/>
      </geometry>
    </visual>
    <collision>
      <origin rpy="0 0 0" xyz="0 0 0"/>
      <geometry>
        <mesh filename="file:///home/astralab/ros/mario_ws/install/mario_description/share/mario_description/meshes/collision/link3_collision.stl"/>
      </geometry>
    </collision>
    <!-- <xacro:if value="${mesh == mount_mesh}">
      <inertial>
        <origin
          xyz="0 0 0.233815804"
          rpy="${mesh_offset_rpy}" />
        <mass value="21.359904"/>
        <inertia ixx="2.013" ixy="5.778e-15" ixz="4.402e-11" iyy="2.016" iyz="1.573E-03" izz="0.4845"/>
      </inertial>
    </xacro:if>

    <xacro:if value="${mesh == body_mesh}">
      <inertial>
        <origin
          xyz="0.000285284 0.00001441 -0.016716995"
          rpy="${mesh_offset_rpy}" />
        <mass value="31.791789"/>
        <inertia ixx="1.910" ixy="-0.0002148" ixz="0.001069" iyy="1.379" iyz="0.000011660298" izz="1.069"/>
      </inertial>
    </xacro:if>     -->
    <inertial>
      <origin rpy="0 0 0" xyz="0.0862514 0.0482967 0.0294908"/>
      <mass value="2.504439505597971"/>
      <inertia ixx="0.010305232382961448" ixy="-0.006258414791800094" ixz="0.004889195914710917" iyy="0.014831193128738006" iyz="0.003010005165727213" izz="0.017904077890816956"/>
    </inertial>
  </link>
  <gazebo reference="arm1_link3">
    <mu1 value="0.2"/>
    <mu2 value="0.2"/>
  </gazebo>
  <joint name="arm1_joint4" type="revolute">
    <parent link="arm1_link3"/>
    <child link="arm1_link4"/>
    <origin rpy="-1.5708 0 0" xyz="0.150 0.426 0"/>
    <axis xyz="0 0 1"/>
    <limit effort="68.0" lower="-6.28" upper="6.28" velocity="0.314"/>
    <dynamics damping="3.6" friction="2.2"/>
  </joint>
  <transmission name="arm1_joint4_transmission">
    <type>transmission_interface/SimpleTransmission</type>
    <joint name="arm1_joint4">
      <hardwareInterface>hardware_interface/PositionJointInterface</hardwareInterface>
    </joint>
    <actuator name="arm1_joint4_actuator">
      <hardwareInterface>hardware_interface/PositionJointInterface</hardwareInterface>
      <mechanicalReduction>100</mechanicalReduction>
    </actuator>
  </transmission>
  <gazebo reference="arm1_joint4">
    <springStiffness value="0.0"/>
    <springReference value="0.0"/>
  </gazebo>
  <link name="arm1_link4">
    <visual>
      <origin rpy="0 0 0" xyz="0 0 0"/>
      <geometry>
        <mesh filename="file:///home/astralab/ros/mario_ws/install/mario_description/share/mario_description/meshes/visual/link4.dae"/>
      </geometry>
    </visual>
    <collision>
      <origin rpy="0 0 0" xyz="0 0 0"/>
      <geometry>
        <mesh filename="file:///home/astralab/ros/mario_ws/install/mario_description/share/mario_description/meshes/collision/link4_collision.stl"/>
      </geometry>
    </collision>
    <!-- <xacro:if value="${mesh == mount_mesh}">
      <inertial>
        <origin
          xyz="0 0 0.233815804"
          rpy="${mesh_offset_rpy}" />
        <mass value="21.359904"/>
        <inertia ixx="2.013" ixy="5.778e-15" ixz="4.402e-11" iyy="2.016" iyz="1.573E-03" izz="0.4845"/>
      </inertial>
    </xacro:if>

    <xacro:if value="${mesh == body_mesh}">
      <inertial>
        <origin
          xyz="0.000285284 0.00001441 -0.016716995"
          rpy="${mesh_offset_rpy}" />
        <mass value="31.791789"/>
        <inertia ixx="1.910" ixy="-0.0002148" ixz="0.001069" iyy="1.379" iyz="0.000011660298" izz="1.069"/>
      </inertial>
    </xacro:if>     -->
    <inertial>
      <origin rpy="0 0 0" xyz="-1.18146e-05 -0.0319256 -0.136235"/>
      <mass value="1.9200253066231572"/>
      <inertia ixx="0.017177998928410643" ixy="-8.139714537428452e-07" ixz="2.3536397956237316e-06" iyy="0.014559744528166288" iyz="0.005460669713950235" izz="0.004335806381461412"/>
    </inertial>
  </link>
  <gazebo reference="arm1_link4">
    <mu1 value="0.2"/>
    <mu2 value="0.2"/>
  </gazebo>
  <joint name="arm1_joint5" type="revolute">
    <parent link="arm1_link4"/>
    <child link="arm1_link5"/>
    <origin rpy="-1.5708 0 0" xyz="0 0 0"/>
    <axis xyz="0 0 1"/>
    <limit effort="19.0" lower="-2.1642" upper="2.1642" velocity="0.314"/>
    <dynamics damping="3.45" friction="3.2"/>
  </joint>
  <transmission name="arm1_joint5_transmission">
    <type>transmission_interface/SimpleTransmission</type>
    <joint name="arm1_joint5">
      <hardwareInterface>hardware_interface/PositionJointInterface</hardwareInterface>
    </joint>
    <actuator name="arm1_joint5_actuator">
      <hardwareInterface>hardware_interface/PositionJointInterface</hardwareInterface>
      <mechanicalReduction>100</mechanicalReduction>
    </actuator>
  </transmission>
  <gazebo reference="arm1_joint5">
    <springStiffness value="0.0"/>
    <springReference value="0.0"/>
  </gazebo>
  <link name="arm1_link5">
    <visual>
      <origin rpy="3.1416 0 0" xyz="0 0 0"/>
      <geometry>
        <mesh filename="file:///home/astralab/ros/mario_ws/install/mario_description/share/mario_description/meshes/visual/link5.dae"/>
      </geometry>
    </visual>
    <collision>
      <origin rpy="3.1416 0 0" xyz="0 0 0"/>
      <geometry>
        <mesh filename="file:///home/astralab/ros/mario_ws/install/mario_description/share/mario_description/meshes/collision/link5_collision.stl"/>
      </geometry>
    </collision>
    <!-- <xacro:if value="${mesh == mount_mesh}">
      <inertial>
        <origin
          xyz="0 0 0.233815804"
          rpy="${mesh_offset_rpy}" />
        <mass value="21.359904"/>
        <inertia ixx="2.013" ixy="5.778e-15" ixz="4.402e-11" iyy="2.016" iyz="1.573E-03" izz="0.4845"/>
      </inertial>
    </xacro:if>

    <xacro:if value="${mesh == body_mesh}">
      <inertial>
        <origin
          xyz="0.000285284 0.00001441 -0.016716995"
          rpy="${mesh_offset_rpy}" />
        <mass value="31.791789"/>
        <inertia ixx="1.910" ixy="-0.0002148" ixz="0.001069" iyy="1.379" iyz="0.000011660298" izz="1.069"/>
      </inertial>
    </xacro:if>     -->
    <inertial>
      <origin rpy="3.1416 0 0" xyz="-8.28403e-09 -0.00504943 0.00366404"/>
      <mass value="1.031470890436948"/>
      <inertia ixx="0.0019164596496307623" ixy="-3.085620805309322e-09" ixz="5.955506321296932e-11" iyy="0.0010199074513527011" iyz="-1.908211134429875e-05" izz="0.001820671319048775"/>
    </inertial>
  </link>
  <gazebo reference="arm1_link5">
    <mu1 value="0.2"/>
    <mu2 value="0.2"/>
  </gazebo>
  <joint name="arm1_joint6" type="revolute">
    <parent link="arm1_link5"/>
    <child link="arm1_link6"/>
    <origin rpy="1.5708 0 0" xyz="0 -0.090 0"/>
    <axis xyz="0 0 1"/>
    <limit effort="19.0" lower="-2.1642" upper="2.1642" velocity="0.314"/>
    <dynamics damping="3.4" friction="1.1"/>
  </joint>
  <transmission name="arm1_joint6_transmission">
    <type>transmission_interface/SimpleTransmission</type>
    <joint name="arm1_joint6">
      <hardwareInterface>hardware_interface/PositionJointInterface</hardwareInterface>
    </joint>
    <actuator name="arm1_joint6_actuator">
      <hardwareInterface>hardware_interface/PositionJointInterface</hardwareInterface>
      <mechanicalReduction>100</mechanicalReduction>
    </actuator>
  </transmission>
  <gazebo reference="arm1_joint6">
    <springStiffness value="0.0"/>
    <springReference value="0.0"/>
  </gazebo>
  <link name="arm1_link6">
    <visual>
      <origin rpy="0 0 0" xyz="0 0 0"/>
      <geometry>
        <mesh filename="file:///home/astralab/ros/mario_ws/install/mario_description/share/mario_description/meshes/visual/link6.dae"/>
      </geometry>
    </visual>
    <collision>
      <origin rpy="0 0 0" xyz="0 0 0"/>
      <geometry>
        <mesh filename="file:///home/astralab/ros/mario_ws/install/mario_description/share/mario_description/meshes/collision/link6_collision.stl"/>
      </geometry>
    </collision>
    <!-- <xacro:if value="${mesh == mount_mesh}">
      <inertial>
        <origin
          xyz="0 0 0.233815804"
          rpy="${mesh_offset_rpy}" />
        <mass value="21.359904"/>
        <inertia ixx="2.013" ixy="5.778e-15" ixz="4.402e-11" iyy="2.016" iyz="1.573E-03" izz="0.4845"/>
      </inertial>
    </xacro:if>

    <xacro:if value="${mesh == body_mesh}">
      <inertial>
        <origin
          xyz="0.000285284 0.00001441 -0.016716995"
          rpy="${mesh_offset_rpy}" />
        <mass value="31.791789"/>
        <inertia ixx="1.910" ixy="-0.0002148" ixz="0.001069" iyy="1.379" iyz="0.000011660298" izz="1.069"/>
      </inertial>
    </xacro:if>     -->
    <inertial>
      <origin rpy="0 0 0" xyz="-4.44071e-05 0.000605308 -0.0167734"/>
      <mass value="0.1847186587233181"/>
      <inertia ixx="8.782147154441072e-05" ixy="-3.449688352192764e-07" ixz="-9.942813426912313e-09" iyy="9.079462468271449e-05" iyz="-4.3907987236311734e-08" izz="0.00015582063271817856"/>
    </inertial>
  </link>
  <gazebo reference="arm1_link6">
    <mu1 value="0.2"/>
    <mu2 value="0.2"/>
  </gazebo>
  <joint name="arm1_si_joint" type="fixed">
    <parent link="arm1_link6"/>
    <child link="arm1_si_link"/>
    <origin rpy="0 0 0" xyz="0 0 0.174"/>
  </joint>
  <link name="arm1_si_link">
    <visual>
      <origin rpy="0 0 0" xyz="0 0 0"/>
      <geometry>
        <mesh filename="file:///home/astralab/ros/mario_ws/install/mario_description/share/mario_description/meshes/visual/siromcx.dae"/>
      </geometry>
    </visual>
    <collision>
      <origin rpy="0 0 0" xyz="0 0 0"/>
      <geometry>
        <mesh filename="file:///home/astralab/ros/mario_ws/install/mario_description/share/mario_description/meshes/collision/siromcx_collision.stl"/>
      </geometry>
    </collision>
    <!-- <xacro:if value="${mesh == mount_mesh}">
      <inertial>
        <origin
          xyz="0 0 0.233815804"
          rpy="${mesh_offset_rpy}" />
        <mass value="21.359904"/>
        <inertia ixx="2.013" ixy="5.778e-15" ixz="4.402e-11" iyy="2.016" iyz="1.573E-03" izz="0.4845"/>
      </inertial>
    </xacro:if>

    <xacro:if value="${mesh == body_mesh}">
      <inertial>
        <origin
          xyz="0.000285284 0.00001441 -0.016716995"
          rpy="${mesh_offset_rpy}" />
        <mass value="31.791789"/>
        <inertia ixx="1.910" ixy="-0.0002148" ixz="0.001069" iyy="1.379" iyz="0.000011660298" izz="1.069"/>
      </inertial>
    </xacro:if>     -->
    <inertial>
      <origin rpy="0 0 0" xyz="0 0 -0.066"/>
      <mass value="1.100"/>
      <inertia ixx="0.003043" ixy="1e-09" ixz="1e-09" iyy="0.003043" iyz="1e-09" izz="0.002891"/>
    </inertial>
  </link>
  <gazebo reference="arm1_si_link">
    <mu1 value="0.85"/>
    <mu2 value="0.85"/>
  </gazebo>
  <link name="arm1_tcp">
  </link>
  <joint name="arm1_tcp_virtual_joint" type="fixed">
    <parent link="arm1_si_link"/>
    <child link="arm1_tcp"/>
    <origin rpy="0 0 0" xyz="0 0 0"/>
  </joint>
  <joint name="arm2_base_joint" type="fixed">
    <parent link="body_link"/>
    <child link="arm2_base_link"/>
    <origin rpy="1.958393 -0.3613671 0.7137244" xyz="0.03157042 -0.221273 -0.127752"/>
  </joint>
  <link name="arm2_base_link">
    <visual>
      <origin rpy="0 0 0" xyz="0 0 0"/>
      <geometry>
        <mesh filename="file:///home/astralab/ros/mario_ws/install/mario_description/share/mario_description/meshes/visual/base_link.dae"/>
      </geometry>
    </visual>
    <collision>
      <origin rpy="0 0 0" xyz="0 0 0"/>
      <geometry>
        <mesh filename="file:///home/astralab/ros/mario_ws/install/mario_description/share/mario_description/meshes/collision/base_link_collision.stl"/>
      </geometry>
    </collision>
    <!-- <xacro:if value="${mesh == mount_mesh}">
      <inertial>
        <origin
          xyz="0 0 0.233815804"
          rpy="${mesh_offset_rpy}" />
        <mass value="21.359904"/>
        <inertia ixx="2.013" ixy="5.778e-15" ixz="4.402e-11" iyy="2.016" iyz="1.573E-03" izz="0.4845"/>
      </inertial>
    </xacro:if>

    <xacro:if value="${mesh == body_mesh}">
      <inertial>
        <origin
          xyz="0.000285284 0.00001441 -0.016716995"
          rpy="${mesh_offset_rpy}" />
        <mass value="31.791789"/>
        <inertia ixx="1.910" ixy="-0.0002148" ixz="0.001069" iyy="1.379" iyz="0.000011660298" izz="1.069"/>
      </inertial>
    </xacro:if>     -->
    <inertial>
      <origin rpy="0 0 0" xyz="-0.000300666 -2.93177e-06 0.0856931"/>
      <mass value="2.9406587184754085"/>
      <inertia ixx="0.01240919194880053" ixy="-6.681227801256974e-07" ixz="-4.2742940760836404e-05" iyy="0.012467411766498215" iyz="-7.075356089603068e-07" izz="0.006257407233473556"/>
    </inertial>
  </link>
  <gazebo reference="arm2_base_link">
    <mu1 value="0.2"/>
    <mu2 value="0.2"/>
  </gazebo>
  <joint name="arm2_joint1" type="revolute">
    <parent link="arm2_base_link"/>
    <child link="arm2_link1"/>
    <origin rpy="0 0 0" xyz="0 0 0.364"/>
    <axis xyz="0 0 1"/>
    <limit effort="200" lower="-6.28" upper="6.28" velocity="0.314"/>
    <dynamics damping="16.6" friction="9.6"/>
  </joint>
  <transmission name="arm2_joint1_transmission">
    <type>transmission_interface/SimpleTransmission</type>
    <joint name="arm2_joint1">
      <hardwareInterface>hardware_interface/PositionJointInterface</hardwareInterface>
    </joint>
    <actuator name="arm2_joint1_actuator">
      <hardwareInterface>hardware_interface/PositionJointInterface</hardwareInterface>
      <mechanicalReduction>100</mechanicalReduction>
    </actuator>
  </transmission>
  <gazebo reference="arm2_joint1">
    <springStiffness value="0.0"/>
    <springReference value="0.0"/>
  </gazebo>
  <link name="arm2_link1">
    <visual>
      <origin rpy="0 0 0" xyz="0 0 0"/>
      <geometry>
        <mesh filename="file:///home/astralab/ros/mario_ws/install/mario_description/share/mario_description/meshes/visual/link1.dae"/>
      </geometry>
    </visual>
    <collision>
      <origin rpy="0 0 0" xyz="0 0 0"/>
      <geometry>
        <mesh filename="file:///home/astralab/ros/mario_ws/install/mario_description/share/mario_description/meshes/collision/link1_collision.stl"/>
      </geometry>
    </collision>
    <!-- <xacro:if value="${mesh == mount_mesh}">
      <inertial>
        <origin
          xyz="0 0 0.233815804"
          rpy="${mesh_offset_rpy}" />
        <mass value="21.359904"/>
        <inertia ixx="2.013" ixy="5.778e-15" ixz="4.402e-11" iyy="2.016" iyz="1.573E-03" izz="0.4845"/>
      </inertial>
    </xacro:if>

    <xacro:if value="${mesh == body_mesh}">
      <inertial>
        <origin
          xyz="0.000285284 0.00001441 -0.016716995"
          rpy="${mesh_offset_rpy}" />
        <mass value="31.791789"/>
        <inertia ixx="1.910" ixy="-0.0002148" ixz="0.001069" iyy="1.379" iyz="0.000011660298" izz="1.069"/>
      </inertial>
    </xacro:if>     -->
    <inertial>
      <origin rpy="0 0 0" xyz="-8.43196e-06 0.0341221 -0.0559626"/>
      <mass value="3.3482163929478057"/>
      <inertia ixx="0.020854379548931976" ixy="6.567223430941928e-07" ixz="-4.3588684092984624e-07" iyy="0.01871416353357244" iyz="-0.004171196153314615" izz="0.008087898002895265"/>
    </inertial>
  </link>
  <gazebo reference="arm2_link1">
    <mu1 value="0.2"/>
    <mu2 value="0.2"/>
  </gazebo>
  <joint name="arm2_joint2" type="revolute">
    <parent link="arm2_link1"/>
    <child link="arm2_link2"/>
    <origin rpy="1.5708 -1.5708 0" xyz="0 0 0"/>
    <axis xyz="0 0 1"/>
    <limit effort="200" lower="-2.3038346" upper="2.3038346" velocity="0.314"/>
    <dynamics damping="12.5" friction="12.1"/>
  </joint>
  <transmission name="arm2_joint2_transmission">
    <type>transmission_interface/SimpleTransmission</type>
    <joint name="arm2_joint2">
      <hardwareInterface>hardware_interface/PositionJointInterface</hardwareInterface>
    </joint>
    <actuator name="arm2_joint2_actuator">
      <hardwareInterface>hardware_interface/PositionJointInterface</hardwareInterface>
      <mechanicalReduction>100</mechanicalReduction>
    </actuator>
  </transmission>
  <gazebo reference="arm2_joint2">
    <springStiffness value="0.0"/>
    <springReference value="0.0"/>
  </gazebo>
  <link name="arm2_link2">
    <visual>
      <origin rpy="0 -3.1416 1.5708" xyz="0 0 0"/>
      <geometry>
        <mesh filename="file:///home/astralab/ros/mario_ws/install/mario_description/share/mario_description/meshes/visual/link2.dae"/>
      </geometry>
    </visual>
    <collision>
      <origin rpy="0 -3.1416 1.5708" xyz="0 0 0"/>
      <geometry>
        <mesh filename="file:///home/astralab/ros/mario_ws/install/mario_description/share/mario_description/meshes/collision/link2_collision.stl"/>
      </geometry>
    </collision>
    <!-- <xacro:if value="${mesh == mount_mesh}">
      <inertial>
        <origin
          xyz="0 0 0.233815804"
          rpy="${mesh_offset_rpy}" />
        <mass value="21.359904"/>
        <inertia ixx="2.013" ixy="5.778e-15" ixz="4.402e-11" iyy="2.016" iyz="1.573E-03" izz="0.4845"/>
      </inertial>
    </xacro:if>

    <xacro:if value="${mesh == body_mesh}">
      <inertial>
        <origin
          xyz="0.000285284 0.00001441 -0.016716995"
          rpy="${mesh_offset_rpy}" />
        <mass value="31.791789"/>
        <inertia ixx="1.910" ixy="-0.0002148" ixz="0.001069" iyy="1.379" iyz="0.000011660298" izz="1.069"/>
      </inertial>
    </xacro:if>     -->
    <inertial>
      <origin rpy="0 -3.1416 1.5708" xyz="7.13145e-05 -0.203029 -0.0324578"/>
      <mass value="5.070470527195393"/>
      <inertia ixx="0.11865370417075823" ixy="-2.375656313165855e-05" ixz="4.136754045829818e-06" iyy="0.009622141254146021" iyz="0.005416309225005912" izz="0.11597628036190748"/>
    </inertial>
  </link>
  <gazebo reference="arm2_link2">
    <mu1 value="0.2"/>
    <mu2 value="0.2"/>
  </gazebo>
  <joint name="arm2_joint3" type="revolute">
    <parent link="arm2_link2"/>
    <child link="arm2_link3"/>
    <origin rpy="-3.1416 0 -1.5708" xyz="0.39 0 0"/>
    <axis xyz="0 0 1"/>
    <limit effort="90" lower="-4.2236968" upper="0.061087" velocity="0.314"/>
    <dynamics damping="4.0" friction="5.5"/>
  </joint>
  <transmission name="arm2_joint3_transmission">
    <type>transmission_interface/SimpleTransmission</type>
    <joint name="arm2_joint3">
      <hardwareInterface>hardware_interface/PositionJointInterface</hardwareInterface>
    </joint>
    <actuator name="arm2_joint3_actuator">
      <hardwareInterface>hardware_interface/PositionJointInterface</hardwareInterface>
      <mechanicalReduction>100</mechanicalReduction>
    </actuator>
  </transmission>
  <gazebo reference="arm2_joint3">
    <springStiffness value="0.0"/>
    <springReference value="0.0"/>
  </gazebo>
  <link name="arm2_link3">
    <visual>
      <origin rpy="0 0 0" xyz="0 0 0"/>
      <geometry>
        <mesh filename="file:///home/astralab/ros/mario_ws/install/mario_description/share/mario_description/meshes/visual/link3.dae"/>
      </geometry>
    </visual>
    <collision>
      <origin rpy="0 0 0" xyz="0 0 0"/>
      <geometry>
        <mesh filename="file:///home/astralab/ros/mario_ws/install/mario_description/share/mario_description/meshes/collision/link3_collision.stl"/>
      </geometry>
    </collision>
    <!-- <xacro:if value="${mesh == mount_mesh}">
      <inertial>
        <origin
          xyz="0 0 0.233815804"
          rpy="${mesh_offset_rpy}" />
        <mass value="21.359904"/>
        <inertia ixx="2.013" ixy="5.778e-15" ixz="4.402e-11" iyy="2.016" iyz="1.573E-03" izz="0.4845"/>
      </inertial>
    </xacro:if>

    <xacro:if value="${mesh == body_mesh}">
      <inertial>
        <origin
          xyz="0.000285284 0.00001441 -0.016716995"
          rpy="${mesh_offset_rpy}" />
        <mass value="31.791789"/>
        <inertia ixx="1.910" ixy="-0.0002148" ixz="0.001069" iyy="1.379" iyz="0.000011660298" izz="1.069"/>
      </inertial>
    </xacro:if>     -->
    <inertial>
      <origin rpy="0 0 0" xyz="0.0862514 0.0482967 0.0294908"/>
      <mass value="2.504439505597971"/>
      <inertia ixx="0.010305232382961448" ixy="-0.006258414791800094" ixz="0.004889195914710917" iyy="0.014831193128738006" iyz="0.003010005165727213" izz="0.017904077890816956"/>
    </inertial>
  </link>
  <gazebo reference="arm2_link3">
    <mu1 value="0.2"/>
    <mu2 value="0.2"/>
  </gazebo>
  <joint name="arm2_joint4" type="revolute">
    <parent link="arm2_link3"/>
    <child link="arm2_link4"/>
    <origin rpy="-1.5708 0 0" xyz="0.150 0.426 0"/>
    <axis xyz="0 0 1"/>
    <limit effort="68.0" lower="-6.28" upper="6.28" velocity="0.314"/>
    <dynamics damping="3.6" friction="2.2"/>
  </joint>
  <transmission name="arm2_joint4_transmission">
    <type>transmission_interface/SimpleTransmission</type>
    <joint name="arm2_joint4">
      <hardwareInterface>hardware_interface/PositionJointInterface</hardwareInterface>
    </joint>
    <actuator name="arm2_joint4_actuator">
      <hardwareInterface>hardware_interface/PositionJointInterface</hardwareInterface>
      <mechanicalReduction>100</mechanicalReduction>
    </actuator>
  </transmission>
  <gazebo reference="arm2_joint4">
    <springStiffness value="0.0"/>
    <springReference value="0.0"/>
  </gazebo>
  <link name="arm2_link4">
    <visual>
      <origin rpy="0 0 0" xyz="0 0 0"/>
      <geometry>
        <mesh filename="file:///home/astralab/ros/mario_ws/install/mario_description/share/mario_description/meshes/visual/link4.dae"/>
      </geometry>
    </visual>
    <collision>
      <origin rpy="0 0 0" xyz="0 0 0"/>
      <geometry>
        <mesh filename="file:///home/astralab/ros/mario_ws/install/mario_description/share/mario_description/meshes/collision/link4_collision.stl"/>
      </geometry>
    </collision>
    <!-- <xacro:if value="${mesh == mount_mesh}">
      <inertial>
        <origin
          xyz="0 0 0.233815804"
          rpy="${mesh_offset_rpy}" />
        <mass value="21.359904"/>
        <inertia ixx="2.013" ixy="5.778e-15" ixz="4.402e-11" iyy="2.016" iyz="1.573E-03" izz="0.4845"/>
      </inertial>
    </xacro:if>

    <xacro:if value="${mesh == body_mesh}">
      <inertial>
        <origin
          xyz="0.000285284 0.00001441 -0.016716995"
          rpy="${mesh_offset_rpy}" />
        <mass value="31.791789"/>
        <inertia ixx="1.910" ixy="-0.0002148" ixz="0.001069" iyy="1.379" iyz="0.000011660298" izz="1.069"/>
      </inertial>
    </xacro:if>     -->
    <inertial>
      <origin rpy="0 0 0" xyz="-1.18146e-05 -0.0319256 -0.136235"/>
      <mass value="1.9200253066231572"/>
      <inertia ixx="0.017177998928410643" ixy="-8.139714537428452e-07" ixz="2.3536397956237316e-06" iyy="0.014559744528166288" iyz="0.005460669713950235" izz="0.004335806381461412"/>
    </inertial>
  </link>
  <gazebo reference="arm2_link4">
    <mu1 value="0.2"/>
    <mu2 value="0.2"/>
  </gazebo>
  <joint name="arm2_joint5" type="revolute">
    <parent link="arm2_link4"/>
    <child link="arm2_link5"/>
    <origin rpy="-1.5708 0 0" xyz="0 0 0"/>
    <axis xyz="0 0 1"/>
    <limit effort="19.0" lower="-2.1642" upper="2.1642" velocity="0.314"/>
    <dynamics damping="3.45" friction="3.2"/>
  </joint>
  <transmission name="arm2_joint5_transmission">
    <type>transmission_interface/SimpleTransmission</type>
    <joint name="arm2_joint5">
      <hardwareInterface>hardware_interface/PositionJointInterface</hardwareInterface>
    </joint>
    <actuator name="arm2_joint5_actuator">
      <hardwareInterface>hardware_interface/PositionJointInterface</hardwareInterface>
      <mechanicalReduction>100</mechanicalReduction>
    </actuator>
  </transmission>
  <gazebo reference="arm2_joint5">
    <springStiffness value="0.0"/>
    <springReference value="0.0"/>
  </gazebo>
  <link name="arm2_link5">
    <visual>
      <origin rpy="3.1416 0 0" xyz="0 0 0"/>
      <geometry>
        <mesh filename="file:///home/astralab/ros/mario_ws/install/mario_description/share/mario_description/meshes/visual/link5.dae"/>
      </geometry>
    </visual>
    <collision>
      <origin rpy="3.1416 0 0" xyz="0 0 0"/>
      <geometry>
        <mesh filename="file:///home/astralab/ros/mario_ws/install/mario_description/share/mario_description/meshes/collision/link5_collision.stl"/>
      </geometry>
    </collision>
    <!-- <xacro:if value="${mesh == mount_mesh}">
      <inertial>
        <origin
          xyz="0 0 0.233815804"
          rpy="${mesh_offset_rpy}" />
        <mass value="21.359904"/>
        <inertia ixx="2.013" ixy="5.778e-15" ixz="4.402e-11" iyy="2.016" iyz="1.573E-03" izz="0.4845"/>
      </inertial>
    </xacro:if>

    <xacro:if value="${mesh == body_mesh}">
      <inertial>
        <origin
          xyz="0.000285284 0.00001441 -0.016716995"
          rpy="${mesh_offset_rpy}" />
        <mass value="31.791789"/>
        <inertia ixx="1.910" ixy="-0.0002148" ixz="0.001069" iyy="1.379" iyz="0.000011660298" izz="1.069"/>
      </inertial>
    </xacro:if>     -->
    <inertial>
      <origin rpy="3.1416 0 0" xyz="-8.28403e-09 -0.00504943 0.00366404"/>
      <mass value="1.031470890436948"/>
      <inertia ixx="0.0019164596496307623" ixy="-3.085620805309322e-09" ixz="5.955506321296932e-11" iyy="0.0010199074513527011" iyz="-1.908211134429875e-05" izz="0.001820671319048775"/>
    </inertial>
  </link>
  <gazebo reference="arm2_link5">
    <mu1 value="0.2"/>
    <mu2 value="0.2"/>
  </gazebo>
  <joint name="arm2_joint6" type="revolute">
    <parent link="arm2_link5"/>
    <child link="arm2_link6"/>
    <origin rpy="1.5708 0 0" xyz="0 -0.090 0"/>
    <axis xyz="0 0 1"/>
    <limit effort="19.0" lower="-2.1642" upper="2.1642" velocity="0.314"/>
    <dynamics damping="3.4" friction="1.1"/>
  </joint>
  <transmission name="arm2_joint6_transmission">
    <type>transmission_interface/SimpleTransmission</type>
    <joint name="arm2_joint6">
      <hardwareInterface>hardware_interface/PositionJointInterface</hardwareInterface>
    </joint>
    <actuator name="arm2_joint6_actuator">
      <hardwareInterface>hardware_interface/PositionJointInterface</hardwareInterface>
      <mechanicalReduction>100</mechanicalReduction>
    </actuator>
  </transmission>
  <gazebo reference="arm2_joint6">
    <springStiffness value="0.0"/>
    <springReference value="0.0"/>
  </gazebo>
  <link name="arm2_link6">
    <visual>
      <origin rpy="0 0 0" xyz="0 0 0"/>
      <geometry>
        <mesh filename="file:///home/astralab/ros/mario_ws/install/mario_description/share/mario_description/meshes/visual/link6.dae"/>
      </geometry>
    </visual>
    <collision>
      <origin rpy="0 0 0" xyz="0 0 0"/>
      <geometry>
        <mesh filename="file:///home/astralab/ros/mario_ws/install/mario_description/share/mario_description/meshes/collision/link6_collision.stl"/>
      </geometry>
    </collision>
    <!-- <xacro:if value="${mesh == mount_mesh}">
      <inertial>
        <origin
          xyz="0 0 0.233815804"
          rpy="${mesh_offset_rpy}" />
        <mass value="21.359904"/>
        <inertia ixx="2.013" ixy="5.778e-15" ixz="4.402e-11" iyy="2.016" iyz="1.573E-03" izz="0.4845"/>
      </inertial>
    </xacro:if>

    <xacro:if value="${mesh == body_mesh}">
      <inertial>
        <origin
          xyz="0.000285284 0.00001441 -0.016716995"
          rpy="${mesh_offset_rpy}" />
        <mass value="31.791789"/>
        <inertia ixx="1.910" ixy="-0.0002148" ixz="0.001069" iyy="1.379" iyz="0.000011660298" izz="1.069"/>
      </inertial>
    </xacro:if>     -->
    <inertial>
      <origin rpy="0 0 0" xyz="-4.44071e-05 0.000605308 -0.0167734"/>
      <mass value="0.1847186587233181"/>
      <inertia ixx="8.782147154441072e-05" ixy="-3.449688352192764e-07" ixz="-9.942813426912313e-09" iyy="9.079462468271449e-05" iyz="-4.3907987236311734e-08" izz="0.00015582063271817856"/>
    </inertial>
  </link>
  <gazebo reference="arm2_link6">
    <mu1 value="0.2"/>
    <mu2 value="0.2"/>
  </gazebo>
  <joint name="arm2_si_joint" type="fixed">
    <parent link="arm2_link6"/>
    <child link="arm2_si_link"/>
    <origin rpy="0 0 0" xyz="0 0 0.174"/>
  </joint>
  <link name="arm2_si_link">
    <visual>
      <origin rpy="0 0 0" xyz="0 0 0"/>
      <geometry>
        <mesh filename="file:///home/astralab/ros/mario_ws/install/mario_description/share/mario_description/meshes/visual/siromcx.dae"/>
      </geometry>
    </visual>
    <collision>
      <origin rpy="0 0 0" xyz="0 0 0"/>
      <geometry>
        <mesh filename="file:///home/astralab/ros/mario_ws/install/mario_description/share/mario_description/meshes/collision/siromcx_collision.stl"/>
      </geometry>
    </collision>
    <!-- <xacro:if value="${mesh == mount_mesh}">
      <inertial>
        <origin
          xyz="0 0 0.233815804"
          rpy="${mesh_offset_rpy}" />
        <mass value="21.359904"/>
        <inertia ixx="2.013" ixy="5.778e-15" ixz="4.402e-11" iyy="2.016" iyz="1.573E-03" izz="0.4845"/>
      </inertial>
    </xacro:if>

    <xacro:if value="${mesh == body_mesh}">
      <inertial>
        <origin
          xyz="0.000285284 0.00001441 -0.016716995"
          rpy="${mesh_offset_rpy}" />
        <mass value="31.791789"/>
        <inertia ixx="1.910" ixy="-0.0002148" ixz="0.001069" iyy="1.379" iyz="0.000011660298" izz="1.069"/>
      </inertial>
    </xacro:if>     -->
    <inertial>
      <origin rpy="0 0 0" xyz="0 0 -0.066"/>
      <mass value="1.100"/>
      <inertia ixx="0.003043" ixy="1e-09" ixz="1e-09" iyy="0.003043" iyz="1e-09" izz="0.002891"/>
    </inertial>
  </link>
  <gazebo reference="arm2_si_link">
    <mu1 value="0.85"/>
    <mu2 value="0.85"/>
  </gazebo>
  <link name="arm2_tcp">
  </link>
  <joint name="arm2_tcp_virtual_joint" type="fixed">
    <parent link="arm2_si_link"/>
    <child link="arm2_tcp"/>
    <origin rpy="0 0 0" xyz="0 0 0"/>
  </joint>
  <joint name="arm3_base_joint" type="fixed">
    <parent link="body_link"/>
    <child link="arm3_base_link"/>
    <origin rpy="-1.958393 -0.3613671 -0.7137244" xyz="0.03157042 0.221273 -0.127752"/>
  </joint>
  <link name="arm3_base_link">
    <visual>
      <origin rpy="0 0 0" xyz="0 0 0"/>
      <geometry>
        <mesh filename="file:///home/astralab/ros/mario_ws/install/mario_description/share/mario_description/meshes/visual/base_link.dae"/>
      </geometry>
    </visual>
    <collision>
      <origin rpy="0 0 0" xyz="0 0 0"/>
      <geometry>
        <mesh filename="file:///home/astralab/ros/mario_ws/install/mario_description/share/mario_description/meshes/collision/base_link_collision.stl"/>
      </geometry>
    </collision>
    <!-- <xacro:if value="${mesh == mount_mesh}">
      <inertial>
        <origin
          xyz="0 0 0.233815804"
          rpy="${mesh_offset_rpy}" />
        <mass value="21.359904"/>
        <inertia ixx="2.013" ixy="5.778e-15" ixz="4.402e-11" iyy="2.016" iyz="1.573E-03" izz="0.4845"/>
      </inertial>
    </xacro:if>

    <xacro:if value="${mesh == body_mesh}">
      <inertial>
        <origin
          xyz="0.000285284 0.00001441 -0.016716995"
          rpy="${mesh_offset_rpy}" />
        <mass value="31.791789"/>
        <inertia ixx="1.910" ixy="-0.0002148" ixz="0.001069" iyy="1.379" iyz="0.000011660298" izz="1.069"/>
      </inertial>
    </xacro:if>     -->
    <inertial>
      <origin rpy="0 0 0" xyz="-0.000300666 -2.93177e-06 0.0856931"/>
      <mass value="2.9406587184754085"/>
      <inertia ixx="0.01240919194880053" ixy="-6.681227801256974e-07" ixz="-4.2742940760836404e-05" iyy="0.012467411766498215" iyz="-7.075356089603068e-07" izz="0.006257407233473556"/>
    </inertial>
  </link>
  <gazebo reference="arm3_base_link">
    <mu1 value="0.2"/>
    <mu2 value="0.2"/>
  </gazebo>
  <joint name="arm3_joint1" type="revolute">
    <parent link="arm3_base_link"/>
    <child link="arm3_link1"/>
    <origin rpy="0 0 0" xyz="0 0 0.364"/>
    <axis xyz="0 0 1"/>
    <limit effort="200" lower="-6.28" upper="6.28" velocity="0.314"/>
    <dynamics damping="16.6" friction="9.6"/>
  </joint>
  <transmission name="arm3_joint1_transmission">
    <type>transmission_interface/SimpleTransmission</type>
    <joint name="arm3_joint1">
      <hardwareInterface>hardware_interface/PositionJointInterface</hardwareInterface>
    </joint>
    <actuator name="arm3_joint1_actuator">
      <hardwareInterface>hardware_interface/PositionJointInterface</hardwareInterface>
      <mechanicalReduction>100</mechanicalReduction>
    </actuator>
  </transmission>
  <gazebo reference="arm3_joint1">
    <springStiffness value="0.0"/>
    <springReference value="0.0"/>
  </gazebo>
  <link name="arm3_link1">
    <visual>
      <origin rpy="0 0 0" xyz="0 0 0"/>
      <geometry>
        <mesh filename="file:///home/astralab/ros/mario_ws/install/mario_description/share/mario_description/meshes/visual/link1.dae"/>
      </geometry>
    </visual>
    <collision>
      <origin rpy="0 0 0" xyz="0 0 0"/>
      <geometry>
        <mesh filename="file:///home/astralab/ros/mario_ws/install/mario_description/share/mario_description/meshes/collision/link1_collision.stl"/>
      </geometry>
    </collision>
    <!-- <xacro:if value="${mesh == mount_mesh}">
      <inertial>
        <origin
          xyz="0 0 0.233815804"
          rpy="${mesh_offset_rpy}" />
        <mass value="21.359904"/>
        <inertia ixx="2.013" ixy="5.778e-15" ixz="4.402e-11" iyy="2.016" iyz="1.573E-03" izz="0.4845"/>
      </inertial>
    </xacro:if>

    <xacro:if value="${mesh == body_mesh}">
      <inertial>
        <origin
          xyz="0.000285284 0.00001441 -0.016716995"
          rpy="${mesh_offset_rpy}" />
        <mass value="31.791789"/>
        <inertia ixx="1.910" ixy="-0.0002148" ixz="0.001069" iyy="1.379" iyz="0.000011660298" izz="1.069"/>
      </inertial>
    </xacro:if>     -->
    <inertial>
      <origin rpy="0 0 0" xyz="-8.43196e-06 0.0341221 -0.0559626"/>
      <mass value="3.3482163929478057"/>
      <inertia ixx="0.020854379548931976" ixy="6.567223430941928e-07" ixz="-4.3588684092984624e-07" iyy="0.01871416353357244" iyz="-0.004171196153314615" izz="0.008087898002895265"/>
    </inertial>
  </link>
  <gazebo reference="arm3_link1">
    <mu1 value="0.2"/>
    <mu2 value="0.2"/>
  </gazebo>
  <joint name="arm3_joint2" type="revolute">
    <parent link="arm3_link1"/>
    <child link="arm3_link2"/>
    <origin rpy="1.5708 -1.5708 0" xyz="0 0 0"/>
    <axis xyz="0 0 1"/>
    <limit effort="200" lower="-2.3038346" upper="2.3038346" velocity="0.314"/>
    <dynamics damping="12.5" friction="12.1"/>
  </joint>
  <transmission name="arm3_joint2_transmission">
    <type>transmission_interface/SimpleTransmission</type>
    <joint name="arm3_joint2">
      <hardwareInterface>hardware_interface/PositionJointInterface</hardwareInterface>
    </joint>
    <actuator name="arm3_joint2_actuator">
      <hardwareInterface>hardware_interface/PositionJointInterface</hardwareInterface>
      <mechanicalReduction>100</mechanicalReduction>
    </actuator>
  </transmission>
  <gazebo reference="arm3_joint2">
    <springStiffness value="0.0"/>
    <springReference value="0.0"/>
  </gazebo>
  <link name="arm3_link2">
    <visual>
      <origin rpy="0 -3.1416 1.5708" xyz="0 0 0"/>
      <geometry>
        <mesh filename="file:///home/astralab/ros/mario_ws/install/mario_description/share/mario_description/meshes/visual/link2.dae"/>
      </geometry>
    </visual>
    <collision>
      <origin rpy="0 -3.1416 1.5708" xyz="0 0 0"/>
      <geometry>
        <mesh filename="file:///home/astralab/ros/mario_ws/install/mario_description/share/mario_description/meshes/collision/link2_collision.stl"/>
      </geometry>
    </collision>
    <!-- <xacro:if value="${mesh == mount_mesh}">
      <inertial>
        <origin
          xyz="0 0 0.233815804"
          rpy="${mesh_offset_rpy}" />
        <mass value="21.359904"/>
        <inertia ixx="2.013" ixy="5.778e-15" ixz="4.402e-11" iyy="2.016" iyz="1.573E-03" izz="0.4845"/>
      </inertial>
    </xacro:if>

    <xacro:if value="${mesh == body_mesh}">
      <inertial>
        <origin
          xyz="0.000285284 0.00001441 -0.016716995"
          rpy="${mesh_offset_rpy}" />
        <mass value="31.791789"/>
        <inertia ixx="1.910" ixy="-0.0002148" ixz="0.001069" iyy="1.379" iyz="0.000011660298" izz="1.069"/>
      </inertial>
    </xacro:if>     -->
    <inertial>
      <origin rpy="0 -3.1416 1.5708" xyz="7.13145e-05 -0.203029 -0.0324578"/>
      <mass value="5.070470527195393"/>
      <inertia ixx="0.11865370417075823" ixy="-2.375656313165855e-05" ixz="4.136754045829818e-06" iyy="0.009622141254146021" iyz="0.005416309225005912" izz="0.11597628036190748"/>
    </inertial>
  </link>
  <gazebo reference="arm3_link2">
    <mu1 value="0.2"/>
    <mu2 value="0.2"/>
  </gazebo>
  <joint name="arm3_joint3" type="revolute">
    <parent link="arm3_link2"/>
    <child link="arm3_link3"/>
    <origin rpy="-3.1416 0 -1.5708" xyz="0.39 0 0"/>
    <axis xyz="0 0 1"/>
    <limit effort="90" lower="-4.2236968" upper="0.061087" velocity="0.314"/>
    <dynamics damping="4.0" friction="5.5"/>
  </joint>
  <transmission name="arm3_joint3_transmission">
    <type>transmission_interface/SimpleTransmission</type>
    <joint name="arm3_joint3">
      <hardwareInterface>hardware_interface/PositionJointInterface</hardwareInterface>
    </joint>
    <actuator name="arm3_joint3_actuator">
      <hardwareInterface>hardware_interface/PositionJointInterface</hardwareInterface>
      <mechanicalReduction>100</mechanicalReduction>
    </actuator>
  </transmission>
  <gazebo reference="arm3_joint3">
    <springStiffness value="0.0"/>
    <springReference value="0.0"/>
  </gazebo>
  <link name="arm3_link3">
    <visual>
      <origin rpy="0 0 0" xyz="0 0 0"/>
      <geometry>
        <mesh filename="file:///home/astralab/ros/mario_ws/install/mario_description/share/mario_description/meshes/visual/link3.dae"/>
      </geometry>
    </visual>
    <collision>
      <origin rpy="0 0 0" xyz="0 0 0"/>
      <geometry>
        <mesh filename="file:///home/astralab/ros/mario_ws/install/mario_description/share/mario_description/meshes/collision/link3_collision.stl"/>
      </geometry>
    </collision>
    <!-- <xacro:if value="${mesh == mount_mesh}">
      <inertial>
        <origin
          xyz="0 0 0.233815804"
          rpy="${mesh_offset_rpy}" />
        <mass value="21.359904"/>
        <inertia ixx="2.013" ixy="5.778e-15" ixz="4.402e-11" iyy="2.016" iyz="1.573E-03" izz="0.4845"/>
      </inertial>
    </xacro:if>

    <xacro:if value="${mesh == body_mesh}">
      <inertial>
        <origin
          xyz="0.000285284 0.00001441 -0.016716995"
          rpy="${mesh_offset_rpy}" />
        <mass value="31.791789"/>
        <inertia ixx="1.910" ixy="-0.0002148" ixz="0.001069" iyy="1.379" iyz="0.000011660298" izz="1.069"/>
      </inertial>
    </xacro:if>     -->
    <inertial>
      <origin rpy="0 0 0" xyz="0.0862514 0.0482967 0.0294908"/>
      <mass value="2.504439505597971"/>
      <inertia ixx="0.010305232382961448" ixy="-0.006258414791800094" ixz="0.004889195914710917" iyy="0.014831193128738006" iyz="0.003010005165727213" izz="0.017904077890816956"/>
    </inertial>
  </link>
  <gazebo reference="arm3_link3">
    <mu1 value="0.2"/>
    <mu2 value="0.2"/>
  </gazebo>
  <joint name="arm3_joint4" type="revolute">
    <parent link="arm3_link3"/>
    <child link="arm3_link4"/>
    <origin rpy="-1.5708 0 0" xyz="0.150 0.426 0"/>
    <axis xyz="0 0 1"/>
    <limit effort="68.0" lower="-6.28" upper="6.28" velocity="0.314"/>
    <dynamics damping="3.6" friction="2.2"/>
  </joint>
  <transmission name="arm3_joint4_transmission">
    <type>transmission_interface/SimpleTransmission</type>
    <joint name="arm3_joint4">
      <hardwareInterface>hardware_interface/PositionJointInterface</hardwareInterface>
    </joint>
    <actuator name="arm3_joint4_actuator">
      <hardwareInterface>hardware_interface/PositionJointInterface</hardwareInterface>
      <mechanicalReduction>100</mechanicalReduction>
    </actuator>
  </transmission>
  <gazebo reference="arm3_joint4">
    <springStiffness value="0.0"/>
    <springReference value="0.0"/>
  </gazebo>
  <link name="arm3_link4">
    <visual>
      <origin rpy="0 0 0" xyz="0 0 0"/>
      <geometry>
        <mesh filename="file:///home/astralab/ros/mario_ws/install/mario_description/share/mario_description/meshes/visual/link4.dae"/>
      </geometry>
    </visual>
    <collision>
      <origin rpy="0 0 0" xyz="0 0 0"/>
      <geometry>
        <mesh filename="file:///home/astralab/ros/mario_ws/install/mario_description/share/mario_description/meshes/collision/link4_collision.stl"/>
      </geometry>
    </collision>
    <!-- <xacro:if value="${mesh == mount_mesh}">
      <inertial>
        <origin
          xyz="0 0 0.233815804"
          rpy="${mesh_offset_rpy}" />
        <mass value="21.359904"/>
        <inertia ixx="2.013" ixy="5.778e-15" ixz="4.402e-11" iyy="2.016" iyz="1.573E-03" izz="0.4845"/>
      </inertial>
    </xacro:if>

    <xacro:if value="${mesh == body_mesh}">
      <inertial>
        <origin
          xyz="0.000285284 0.00001441 -0.016716995"
          rpy="${mesh_offset_rpy}" />
        <mass value="31.791789"/>
        <inertia ixx="1.910" ixy="-0.0002148" ixz="0.001069" iyy="1.379" iyz="0.000011660298" izz="1.069"/>
      </inertial>
    </xacro:if>     -->
    <inertial>
      <origin rpy="0 0 0" xyz="-1.18146e-05 -0.0319256 -0.136235"/>
      <mass value="1.9200253066231572"/>
      <inertia ixx="0.017177998928410643" ixy="-8.139714537428452e-07" ixz="2.3536397956237316e-06" iyy="0.014559744528166288" iyz="0.005460669713950235" izz="0.004335806381461412"/>
    </inertial>
  </link>
  <gazebo reference="arm3_link4">
    <mu1 value="0.2"/>
    <mu2 value="0.2"/>
  </gazebo>
  <joint name="arm3_joint5" type="revolute">
    <parent link="arm3_link4"/>
    <child link="arm3_link5"/>
    <origin rpy="-1.5708 0 0" xyz="0 0 0"/>
    <axis xyz="0 0 1"/>
    <limit effort="19.0" lower="-2.1642" upper="2.1642" velocity="0.314"/>
    <dynamics damping="3.45" friction="3.2"/>
  </joint>
  <transmission name="arm3_joint5_transmission">
    <type>transmission_interface/SimpleTransmission</type>
    <joint name="arm3_joint5">
      <hardwareInterface>hardware_interface/PositionJointInterface</hardwareInterface>
    </joint>
    <actuator name="arm3_joint5_actuator">
      <hardwareInterface>hardware_interface/PositionJointInterface</hardwareInterface>
      <mechanicalReduction>100</mechanicalReduction>
    </actuator>
  </transmission>
  <gazebo reference="arm3_joint5">
    <springStiffness value="0.0"/>
    <springReference value="0.0"/>
  </gazebo>
  <link name="arm3_link5">
    <visual>
      <origin rpy="3.1416 0 0" xyz="0 0 0"/>
      <geometry>
        <mesh filename="file:///home/astralab/ros/mario_ws/install/mario_description/share/mario_description/meshes/visual/link5.dae"/>
      </geometry>
    </visual>
    <collision>
      <origin rpy="3.1416 0 0" xyz="0 0 0"/>
      <geometry>
        <mesh filename="file:///home/astralab/ros/mario_ws/install/mario_description/share/mario_description/meshes/collision/link5_collision.stl"/>
      </geometry>
    </collision>
    <!-- <xacro:if value="${mesh == mount_mesh}">
      <inertial>
        <origin
          xyz="0 0 0.233815804"
          rpy="${mesh_offset_rpy}" />
        <mass value="21.359904"/>
        <inertia ixx="2.013" ixy="5.778e-15" ixz="4.402e-11" iyy="2.016" iyz="1.573E-03" izz="0.4845"/>
      </inertial>
    </xacro:if>

    <xacro:if value="${mesh == body_mesh}">
      <inertial>
        <origin
          xyz="0.000285284 0.00001441 -0.016716995"
          rpy="${mesh_offset_rpy}" />
        <mass value="31.791789"/>
        <inertia ixx="1.910" ixy="-0.0002148" ixz="0.001069" iyy="1.379" iyz="0.000011660298" izz="1.069"/>
      </inertial>
    </xacro:if>     -->
    <inertial>
      <origin rpy="3.1416 0 0" xyz="-8.28403e-09 -0.00504943 0.00366404"/>
      <mass value="1.031470890436948"/>
      <inertia ixx="0.0019164596496307623" ixy="-3.085620805309322e-09" ixz="5.955506321296932e-11" iyy="0.0010199074513527011" iyz="-1.908211134429875e-05" izz="0.001820671319048775"/>
    </inertial>
  </link>
  <gazebo reference="arm3_link5">
    <mu1 value="0.2"/>
    <mu2 value="0.2"/>
  </gazebo>
  <joint name="arm3_joint6" type="revolute">
    <parent link="arm3_link5"/>
    <child link="arm3_link6"/>
    <origin rpy="1.5708 0 0" xyz="0 -0.090 0"/>
    <axis xyz="0 0 1"/>
    <limit effort="19.0" lower="-2.1642" upper="2.1642" velocity="0.314"/>
    <dynamics damping="3.4" friction="1.1"/>
  </joint>
  <transmission name="arm3_joint6_transmission">
    <type>transmission_interface/SimpleTransmission</type>
    <joint name="arm3_joint6">
      <hardwareInterface>hardware_interface/PositionJointInterface</hardwareInterface>
    </joint>
    <actuator name="arm3_joint6_actuator">
      <hardwareInterface>hardware_interface/PositionJointInterface</hardwareInterface>
      <mechanicalReduction>100</mechanicalReduction>
    </actuator>
  </transmission>
  <gazebo reference="arm3_joint6">
    <springStiffness value="0.0"/>
    <springReference value="0.0"/>
  </gazebo>
  <link name="arm3_link6">
    <visual>
      <origin rpy="0 0 0" xyz="0 0 0"/>
      <geometry>
        <mesh filename="file:///home/astralab/ros/mario_ws/install/mario_description/share/mario_description/meshes/visual/link6.dae"/>
      </geometry>
    </visual>
    <collision>
      <origin rpy="0 0 0" xyz="0 0 0"/>
      <geometry>
        <mesh filename="file:///home/astralab/ros/mario_ws/install/mario_description/share/mario_description/meshes/collision/link6_collision.stl"/>
      </geometry>
    </collision>
    <!-- <xacro:if value="${mesh == mount_mesh}">
      <inertial>
        <origin
          xyz="0 0 0.233815804"
          rpy="${mesh_offset_rpy}" />
        <mass value="21.359904"/>
        <inertia ixx="2.013" ixy="5.778e-15" ixz="4.402e-11" iyy="2.016" iyz="1.573E-03" izz="0.4845"/>
      </inertial>
    </xacro:if>

    <xacro:if value="${mesh == body_mesh}">
      <inertial>
        <origin
          xyz="0.000285284 0.00001441 -0.016716995"
          rpy="${mesh_offset_rpy}" />
        <mass value="31.791789"/>
        <inertia ixx="1.910" ixy="-0.0002148" ixz="0.001069" iyy="1.379" iyz="0.000011660298" izz="1.069"/>
      </inertial>
    </xacro:if>     -->
    <inertial>
      <origin rpy="0 0 0" xyz="-4.44071e-05 0.000605308 -0.0167734"/>
      <mass value="0.1847186587233181"/>
      <inertia ixx="8.782147154441072e-05" ixy="-3.449688352192764e-07" ixz="-9.942813426912313e-09" iyy="9.079462468271449e-05" iyz="-4.3907987236311734e-08" izz="0.00015582063271817856"/>
    </inertial>
  </link>
  <gazebo reference="arm3_link6">
    <mu1 value="0.2"/>
    <mu2 value="0.2"/>
  </gazebo>
  <joint name="arm3_si_joint" type="fixed">
    <parent link="arm3_link6"/>
    <child link="arm3_si_link"/>
    <origin rpy="0 0 0" xyz="0 0 0.174"/>
  </joint>
  <link name="arm3_si_link">
    <visual>
      <origin rpy="0 0 0" xyz="0 0 0"/>
      <geometry>
        <mesh filename="file:///home/astralab/ros/mario_ws/install/mario_description/share/mario_description/meshes/visual/siromcx.dae"/>
      </geometry>
    </visual>
    <collision>
      <origin rpy="0 0 0" xyz="0 0 0"/>
      <geometry>
        <mesh filename="file:///home/astralab/ros/mario_ws/install/mario_description/share/mario_description/meshes/collision/siromcx_collision.stl"/>
      </geometry>
    </collision>
    <!-- <xacro:if value="${mesh == mount_mesh}">
      <inertial>
        <origin
          xyz="0 0 0.233815804"
          rpy="${mesh_offset_rpy}" />
        <mass value="21.359904"/>
        <inertia ixx="2.013" ixy="5.778e-15" ixz="4.402e-11" iyy="2.016" iyz="1.573E-03" izz="0.4845"/>
      </inertial>
    </xacro:if>

    <xacro:if value="${mesh == body_mesh}">
      <inertial>
        <origin
          xyz="0.000285284 0.00001441 -0.016716995"
          rpy="${mesh_offset_rpy}" />
        <mass value="31.791789"/>
        <inertia ixx="1.910" ixy="-0.0002148" ixz="0.001069" iyy="1.379" iyz="0.000011660298" izz="1.069"/>
      </inertial>
    </xacro:if>     -->
    <inertial>
      <origin rpy="0 0 0" xyz="0 0 -0.066"/>
      <mass value="1.100"/>
      <inertia ixx="0.003043" ixy="1e-09" ixz="1e-09" iyy="0.003043" iyz="1e-09" izz="0.002891"/>
    </inertial>
  </link>
  <gazebo reference="arm3_si_link">
    <mu1 value="0.85"/>
    <mu2 value="0.85"/>
  </gazebo>
  <link name="arm3_tcp">
  </link>
  <joint name="arm3_tcp_virtual_joint" type="fixed">
    <parent link="arm3_si_link"/>
    <child link="arm3_tcp"/>
    <origin rpy="0 0 0" xyz="0 0 0"/>
  </joint>
  <ros2_control name="arm1_system" type="system">
    <!-- Hardware -->
    <hardware>
      <plugin>fake_components/GenericSystem</plugin>
    </hardware>
    <!-- Joint 1 -->
    <joint name="arm1_joint1">
      <command_interface name="position">
        <param name="min">-6.283185307179586</param>
        <param name="max">6.283185307179586</param>
      </command_interface>
      <command_interface name="velocity">
        <param name="min">-0.314</param>
        <param name="max">0.314</param>
      </command_interface>
      <state_interface name="position">
        <param name="initial_value">0</param>
      </state_interface>
      <state_interface name="velocity">
        <param name="initial_value">0.0</param>
      </state_interface>
    </joint>
    <!-- Joint 2 -->
    <joint name="arm1_joint2">
      <!-- <xacro:if value="${'position' in command_interface}">
                <command_interface name="position"/>
            </xacro:if>
            <xacro:if value="${'velocity' in command_interface}">
                <command_interface name="velocity"/>
            </xacro:if>
            <state_interface name="position">
                <param name="initial_value">${initial_positions['joint2']}</param>
            </state_interface>
            <state_interface name="velocity">
                <param name="initial_value">0.0</param>
            </state_interface> -->
      <command_interface name="position">
        <param name="min">-2.3038346</param>
        <param name="max">2.3038346</param>
      </command_interface>
      <command_interface name="velocity">
        <param name="min">-0.314</param>
        <param name="max">0.314</param>
      </command_interface>
      <state_interface name="position">
        <param name="initial_value">0</param>
      </state_interface>
      <state_interface name="velocity">
        <param name="initial_value">0.0</param>
      </state_interface>
    </joint>
    <!-- Joint 3 -->
    <joint name="arm1_joint3">
      <command_interface name="position">
        <param name="min">-4.2236968</param>
        <param name="max">0.061087</param>
      </command_interface>
      <command_interface name="velocity">
        <param name="min">-0.314</param>
        <param name="max">0.314</param>
      </command_interface>
      <state_interface name="position">
        <param name="initial_value">0</param>
      </state_interface>
      <state_interface name="velocity">
        <param name="initial_value">0.0</param>
      </state_interface>
    </joint>
    <!-- Joint 4 -->
    <joint name="arm1_joint4">
      <command_interface name="position">
        <param name="min">-6.283185307179586</param>
        <param name="max">6.283185307179586</param>
      </command_interface>
      <command_interface name="velocity">
        <param name="min">-0.314</param>
        <param name="max">0.314</param>
      </command_interface>
      <state_interface name="position">
        <param name="initial_value">0</param>
      </state_interface>
      <state_interface name="velocity">
        <param name="initial_value">0.0</param>
      </state_interface>
    </joint>
    <!-- Joint 5 -->
    <joint name="arm1_joint5">
      <command_interface name="position">
        <param name="min">-2.1642</param>
        <param name="max">2.1642</param>
      </command_interface>
      <command_interface name="velocity">
        <param name="min">-0.314</param>
        <param name="max">0.314</param>
      </command_interface>
      <state_interface name="position">
        <param name="initial_value">0</param>
      </state_interface>
      <state_interface name="velocity">
        <param name="initial_value">0.0</param>
      </state_interface>
    </joint>
    <!-- Joint 6 -->
    <joint name="arm1_joint6">
      <command_interface name="position">
        <param name="min">-6.283185307179586</param>
        <param name="max">6.283185307179586</param>
      </command_interface>
      <command_interface name="velocity">
        <param name="min">-0.314</param>
        <param name="max">0.314</param>
      </command_interface>
      <state_interface name="position">
        <param name="initial_value">0</param>
      </state_interface>
      <state_interface name="velocity">
        <param name="initial_value">0.0</param>
      </state_interface>
    </joint>
  </ros2_control>
  <ros2_control name="arm2_system" type="system">
    <!-- Hardware -->
    <hardware>
      <plugin>fake_components/GenericSystem</plugin>
    </hardware>
    <!-- Joint 1 -->
    <joint name="arm2_joint1">
      <command_interface name="position">
        <param name="min">-6.283185307179586</param>
        <param name="max">6.283185307179586</param>
      </command_interface>
      <command_interface name="velocity">
        <param name="min">-0.314</param>
        <param name="max">0.314</param>
      </command_interface>
      <state_interface name="position">
        <param name="initial_value">0</param>
      </state_interface>
      <state_interface name="velocity">
        <param name="initial_value">0.0</param>
      </state_interface>
    </joint>
    <!-- Joint 2 -->
    <joint name="arm2_joint2">
      <!-- <xacro:if value="${'position' in command_interface}">
                <command_interface name="position"/>
            </xacro:if>
            <xacro:if value="${'velocity' in command_interface}">
                <command_interface name="velocity"/>
            </xacro:if>
            <state_interface name="position">
                <param name="initial_value">${initial_positions['joint2']}</param>
            </state_interface>
            <state_interface name="velocity">
                <param name="initial_value">0.0</param>
            </state_interface> -->
      <command_interface name="position">
        <param name="min">-2.3038346</param>
        <param name="max">2.3038346</param>
      </command_interface>
      <command_interface name="velocity">
        <param name="min">-0.314</param>
        <param name="max">0.314</param>
      </command_interface>
      <state_interface name="position">
        <param name="initial_value">0</param>
      </state_interface>
      <state_interface name="velocity">
        <param name="initial_value">0.0</param>
      </state_interface>
    </joint>
    <!-- Joint 3 -->
    <joint name="arm2_joint3">
      <command_interface name="position">
        <param name="min">-4.2236968</param>
        <param name="max">0.061087</param>
      </command_interface>
      <command_interface name="velocity">
        <param name="min">-0.314</param>
        <param name="max">0.314</param>
      </command_interface>
      <state_interface name="position">
        <param name="initial_value">0</param>
      </state_interface>
      <state_interface name="velocity">
        <param name="initial_value">0.0</param>
      </state_interface>
    </joint>
    <!-- Joint 4 -->
    <joint name="arm2_joint4">
      <command_interface name="position">
        <param name="min">-6.283185307179586</param>
        <param name="max">6.283185307179586</param>
      </command_interface>
      <command_interface name="velocity">
        <param name="min">-0.314</param>
        <param name="max">0.314</param>
      </command_interface>
      <state_interface name="position">
        <param name="initial_value">0</param>
      </state_interface>
      <state_interface name="velocity">
        <param name="initial_value">0.0</param>
      </state_interface>
    </joint>
    <!-- Joint 5 -->
    <joint name="arm2_joint5">
      <command_interface name="position">
        <param name="min">-2.1642</param>
        <param name="max">2.1642</param>
      </command_interface>
      <command_interface name="velocity">
        <param name="min">-0.314</param>
        <param name="max">0.314</param>
      </command_interface>
      <state_interface name="position">
        <param name="initial_value">0</param>
      </state_interface>
      <state_interface name="velocity">
        <param name="initial_value">0.0</param>
      </state_interface>
    </joint>
    <!-- Joint 6 -->
    <joint name="arm2_joint6">
      <command_interface name="position">
        <param name="min">-6.283185307179586</param>
        <param name="max">6.283185307179586</param>
      </command_interface>
      <command_interface name="velocity">
        <param name="min">-0.314</param>
        <param name="max">0.314</param>
      </command_interface>
      <state_interface name="position">
        <param name="initial_value">0</param>
      </state_interface>
      <state_interface name="velocity">
        <param name="initial_value">0.0</param>
      </state_interface>
    </joint>
  </ros2_control>
  <ros2_control name="arm3_system" type="system">
    <!-- Hardware -->
    <hardware>
      <plugin>fake_components/GenericSystem</plugin>
    </hardware>
    <!-- Joint 1 -->
    <joint name="arm3_joint1">
      <command_interface name="position">
        <param name="min">-6.283185307179586</param>
        <param name="max">6.283185307179586</param>
      </command_interface>
      <command_interface name="velocity">
        <param name="min">-0.314</param>
        <param name="max">0.314</param>
      </command_interface>
      <state_interface name="position">
        <param name="initial_value">0</param>
      </state_interface>
      <state_interface name="velocity">
        <param name="initial_value">0.0</param>
      </state_interface>
    </joint>
    <!-- Joint 2 -->
    <joint name="arm3_joint2">
      <!-- <xacro:if value="${'position' in command_interface}">
                <command_interface name="position"/>
            </xacro:if>
            <xacro:if value="${'velocity' in command_interface}">
                <command_interface name="velocity"/>
            </xacro:if>
            <state_interface name="position">
                <param name="initial_value">${initial_positions['joint2']}</param>
            </state_interface>
            <state_interface name="velocity">
                <param name="initial_value">0.0</param>
            </state_interface> -->
      <command_interface name="position">
        <param name="min">-2.3038346</param>
        <param name="max">2.3038346</param>
      </command_interface>
      <command_interface name="velocity">
        <param name="min">-0.314</param>
        <param name="max">0.314</param>
      </command_interface>
      <state_interface name="position">
        <param name="initial_value">0</param>
      </state_interface>
      <state_interface name="velocity">
        <param name="initial_value">0.0</param>
      </state_interface>
    </joint>
    <!-- Joint 3 -->
    <joint name="arm3_joint3">
      <command_interface name="position">
        <param name="min">-4.2236968</param>
        <param name="max">0.061087</param>
      </command_interface>
      <command_interface name="velocity">
        <param name="min">-0.314</param>
        <param name="max">0.314</param>
      </command_interface>
      <state_interface name="position">
        <param name="initial_value">0</param>
      </state_interface>
      <state_interface name="velocity">
        <param name="initial_value">0.0</param>
      </state_interface>
    </joint>
    <!-- Joint 4 -->
    <joint name="arm3_joint4">
      <command_interface name="position">
        <param name="min">-6.283185307179586</param>
        <param name="max">6.283185307179586</param>
      </command_interface>
      <command_interface name="velocity">
        <param name="min">-0.314</param>
        <param name="max">0.314</param>
      </command_interface>
      <state_interface name="position">
        <param name="initial_value">0</param>
      </state_interface>
      <state_interface name="velocity">
        <param name="initial_value">0.0</param>
      </state_interface>
    </joint>
    <!-- Joint 5 -->
    <joint name="arm3_joint5">
      <command_interface name="position">
        <param name="min">-2.1642</param>
        <param name="max">2.1642</param>
      </command_interface>
      <command_interface name="velocity">
        <param name="min">-0.314</param>
        <param name="max">0.314</param>
      </command_interface>
      <state_interface name="position">
        <param name="initial_value">0</param>
      </state_interface>
      <state_interface name="velocity">
        <param name="initial_value">0.0</param>
      </state_interface>
    </joint>
    <!-- Joint 6 -->
    <joint name="arm3_joint6">
      <command_interface name="position">
        <param name="min">-6.283185307179586</param>
        <param name="max">6.283185307179586</param>
      </command_interface>
      <command_interface name="velocity">
        <param name="min">-0.314</param>
        <param name="max">0.314</param>
      </command_interface>
      <state_interface name="position">
        <param name="initial_value">0</param>
      </state_interface>
      <state_interface name="velocity">
        <param name="initial_value">0.0</param>
      </state_interface>
    </joint>
  </ros2_control>
</robot>
